Traceback (most recent call last):
  File "/usr/share/miniconda3/envs/spicejb/lib/python3.7/site-packages/jupyter_cache/executors/utils.py", line 56, in single_nb_execution
    record_timing=False,
  File "/usr/share/miniconda3/envs/spicejb/lib/python3.7/site-packages/nbclient/client.py", line 1204, in execute
    return NotebookClient(nb=nb, resources=resources, km=km, **kwargs).execute()
  File "/usr/share/miniconda3/envs/spicejb/lib/python3.7/site-packages/nbclient/util.py", line 84, in wrapped
    return just_run(coro(*args, **kwargs))
  File "/usr/share/miniconda3/envs/spicejb/lib/python3.7/site-packages/nbclient/util.py", line 62, in just_run
    return loop.run_until_complete(coro)
  File "/usr/share/miniconda3/envs/spicejb/lib/python3.7/asyncio/base_events.py", line 587, in run_until_complete
    return future.result()
  File "/usr/share/miniconda3/envs/spicejb/lib/python3.7/site-packages/nbclient/client.py", line 664, in async_execute
    cell, index, execution_count=self.code_cells_executed + 1
  File "/usr/share/miniconda3/envs/spicejb/lib/python3.7/site-packages/nbclient/client.py", line 965, in async_execute_cell
    await self._check_raise_for_error(cell, cell_index, exec_reply)
  File "/usr/share/miniconda3/envs/spicejb/lib/python3.7/site-packages/nbclient/client.py", line 862, in _check_raise_for_error
    raise CellExecutionError.from_cell_and_msg(cell, exec_reply_content)
nbclient.exceptions.CellExecutionError: An error occurred while executing the following cell:
------------------
spice23 = Registrar('SPICE', 10)

spice23.roster() #empty roster

spice23.enroll('Macey')
spice23.enroll('Tvisha')
spice23.enroll('John')
spice23.enroll('Olivia')
spice23.roster() #four students enrolled

spice23.drop('John')
spice23.roster() #three students enrolled

spice23.enroll('Chris')
spice23.enroll('Nikash')
spice23.enroll('Advait')
spice23.enroll('Rithvik')
spice23.enroll('Julia')
spice23.enroll('Fatiha')
spice23.enroll('Leila') #max enrollment reached
spice23.roster()

spice23.enroll('Qixiu') #should give an error
------------------

[0;31m---------------------------------------------------------------------------[0m
[0;31mException[0m                                 Traceback (most recent call last)
[0;32m/tmp/ipykernel_6347/1372793491.py[0m in [0;36m<module>[0;34m[0m
[1;32m     21[0m [0mspice23[0m[0;34m.[0m[0mroster[0m[0;34m([0m[0;34m)[0m[0;34m[0m[0;34m[0m[0m
[1;32m     22[0m [0;34m[0m[0m
[0;32m---> 23[0;31m [0mspice23[0m[0;34m.[0m[0menroll[0m[0;34m([0m[0;34m'Qixiu'[0m[0;34m)[0m [0;31m#should give an error[0m[0;34m[0m[0;34m[0m[0m
[0m
[0;32m/tmp/ipykernel_6347/3931153931.py[0m in [0;36menroll[0;34m(self, student)[0m
[1;32m     11[0m             [0mself[0m[0;34m.[0m[0mincrement[0m[0;34m([0m[0;34m)[0m [0;31m#uses Counter's increment method[0m[0;34m[0m[0;34m[0m[0m
[1;32m     12[0m         [0;32melse[0m[0;34m:[0m[0;34m[0m[0;34m[0m[0m
[0;32m---> 13[0;31m             [0;32mraise[0m [0mException[0m[0;34m([0m[0;34m'enrollment cap reached, cannot enroll student'[0m[0;34m)[0m[0;34m[0m[0;34m[0m[0m
[0m[1;32m     14[0m [0;34m[0m[0m
[1;32m     15[0m     [0;32mdef[0m [0mdrop[0m[0;34m([0m[0mself[0m[0;34m,[0m [0mstudent[0m[0;34m)[0m[0;34m:[0m[0;34m[0m[0;34m[0m[0m

[0;31mException[0m: enrollment cap reached, cannot enroll student
Exception: enrollment cap reached, cannot enroll student

